Workbook

Sheet Setup
B2: Write out your own habits here: | D2: Choose emojis | E2: ⤵️⤵️⤵️ | G2: Emoji keyboard shortcut:
B3: =IFERROR(FILTER(raw_trackers!B2:B, raw_trackers!B2:B<>""), "") | D3: 0 habits done | G3: 🪟: Press Windows + ; (semi-colon) or Windows + . (period)
D4: 1 habit done | E4: 😶 | G4: 🍏: Control + Command + Spacebar
D5: 2 habits done | E5: 🙂
D6: 3 habits done | E6: 😊
D7: 4 habits done | E7: 😍
D8: 5 habits done | E8: 🚀
D9: 6 habits or more | E9: 🔥

Sheet Habits Tracker 2026
B1: Year: | D1: 2026 | I1: =DATE($D$1,1,1) | J1: =I1 | K1: =J1+1 | L1: =K1+1 | M1: =L1+1 | N1: =M1+1 | O1: =N1+1 | P1: =O1+1 | Q1: =P1+1 | R1: =Q1+1 | ... AN1: =AM1+1 | AO1: TOTAL | AQ1: current streak 🔥 | AR1: longest streak😼 | AS1: Goal🔢 | AT1: Progress 📈
B2: Week start: | E2: Monday | I2: =D1 | J2: =J1 | K2: =K1 | L2: =L1 | M2: =M1 | N2: =N1 | O2: =O1 | P2: =P1 | Q2: =Q1 | ... AN2: =AN1
B3: Пн | C3: Вт | D3: Ср | E3: Чт | F3: Пт | G3: Сб | H3: Вс | I3: =ARRAYFORMULA(Setup!B3:B22) | AO3: =SUM(J3:AN3) | AT3: =IF(AS3>0, AO3/AS3, "")
A4: =WEEKNUM(B4,2) | B4: =IFERROR(DATE($D$1, MONTH(I1), 1) - WEEKDAY(DATE($D$1, MONTH(I1), 1), 2) + 1 + 0*7 + 0, "") | C4: =IFERROR(DATE($D$1, MONTH(I1), 1) - WEEKDAY(DATE($D$1, MONTH(I1), 1), 2) + 1 + 0*7 + 1, "") | D4: =IFERROR(DATE($D$1, MONTH(I1), 1) - WEEKDAY(DATE($D$1, MONTH(I1), 1), 2) + 1 + 0*7 + 2, "") | E4: =IFERROR(DATE($D$1, MONTH(I1), 1) - WEEKDAY(DATE($D$1, MONTH(I1), 1), 2) + 1 + 0*7 + 3, "") | F4: =IFERROR(DATE($D$1, MONTH(I1), 1) - WEEKDAY(DATE($D$1, MONTH(I1), 1), 2) + 1 + 0*7 + 4, "") | G4: =IFERROR(DATE($D$1, MONTH(I1), 1) - WEEKDAY(DATE($D$1, MONTH(I1), 1), 2) + 1 + 0*7 + 5, "") | H4: =IFERROR(DATE($D$1, MONTH(I1), 1) - WEEKDAY(DATE($D$1, MONTH(I1), 1), 2) + 1 + 0*7 + 6, "") | AO4: =SUM(J4:AN4) | AT4: =IF(AS4>0, AO4/AS4, "")
A5: =WEEKNUM(B5,2) | B5: =IFERROR(DATE($D$1, MONTH(I1), 1) - WEEKDAY(DATE($D$1, MONTH(I1), 1), 2) + 1 + 1*7 + 0, "") | C5: =IFERROR(DATE($D$1, MONTH(I1), 1) - WEEKDAY(DATE($D$1, MONTH(I1), 1), 2) + 1 + 1*7 + 1, "") | D5: =IFERROR(DATE($D$1, MONTH(I1), 1) - WEEKDAY(DATE($D$1, MONTH(I1), 1), 2) + 1 + 1*7 + 2, "") | E5: =IFERROR(DATE($D$1, MONTH(I1), 1) - WEEKDAY(DATE($D$1, MONTH(I1), 1), 2) + 1 + 1*7 + 3, "") | F5: =IFERROR(DATE($D$1, MONTH(I1), 1) - WEEKDAY(DATE($D$1, MONTH(I1), 1), 2) + 1 + 1*7 + 4, "") | G5: =IFERROR(DATE($D$1, MONTH(I1), 1) - WEEKDAY(DATE($D$1, MONTH(I1), 1), 2) + 1 + 1*7 + 5, "") | H5: =IFERROR(DATE($D$1, MONTH(I1), 1) - WEEKDAY(DATE($D$1, MONTH(I1), 1), 2) + 1 + 1*7 + 6, "") | AO5: =SUM(J5:AN5) | AT5: =IF(AS5>0, AO5/AS5, "")
A6: =WEEKNUM(B6,2) | B6: =IFERROR(DATE($D$1, MONTH(I1), 1) - WEEKDAY(DATE($D$1, MONTH(I1), 1), 2) + 1 + 2*7 + 0, "") | C6: =IFERROR(DATE($D$1, MONTH(I1), 1) - WEEKDAY(DATE($D$1, MONTH(I1), 1), 2) + 1 + 2*7 + 1, "") | D6: =IFERROR(DATE($D$1, MONTH(I1), 1) - WEEKDAY(DATE($D$1, MONTH(I1), 1), 2) + 1 + 2*7 + 2, "") | E6: =IFERROR(DATE($D$1, MONTH(I1), 1) - WEEKDAY(DATE($D$1, MONTH(I1), 1), 2) + 1 + 2*7 + 3, "") | F6: =IFERROR(DATE($D$1, MONTH(I1), 1) - WEEKDAY(DATE($D$1, MONTH(I1), 1), 2) + 1 + 2*7 + 4, "") | G6: =IFERROR(DATE($D$1, MONTH(I1), 1) - WEEKDAY(DATE($D$1, MONTH(I1), 1), 2) + 1 + 2*7 + 5, "") | H6: =IFERROR(DATE($D$1, MONTH(I1), 1) - WEEKDAY(DATE($D$1, MONTH(I1), 1), 2) + 1 + 2*7 + 6, "") | AO6: =SUM(J6:AN6) | AT6: =IF(AS6>0, AO6/AS6, "")
A7: =WEEKNUM(B7,2) | B7: =IFERROR(DATE($D$1, MONTH(I1), 1) - WEEKDAY(DATE($D$1, MONTH(I1), 1), 2) + 1 + 3*7 + 0, "") | C7: =IFERROR(DATE($D$1, MONTH(I1), 1) - WEEKDAY(DATE($D$1, MONTH(I1), 1), 2) + 1 + 3*7 + 1, "") | D7: =IFERROR(DATE($D$1, MONTH(I1), 1) - WEEKDAY(DATE($D$1, MONTH(I1), 1), 2) + 1 + 3*7 + 2, "") | E7: =IFERROR(DATE($D$1, MONTH(I1), 1) - WEEKDAY(DATE($D$1, MONTH(I1), 1), 2) + 1 + 3*7 + 3, "") | F7: =IFERROR(DATE($D$1, MONTH(I1), 1) - WEEKDAY(DATE($D$1, MONTH(I1), 1), 2) + 1 + 3*7 + 4, "") | G7: =IFERROR(DATE($D$1, MONTH(I1), 1) - WEEKDAY(DATE($D$1, MONTH(I1), 1), 2) + 1 + 3*7 + 5, "") | H7: =IFERROR(DATE($D$1, MONTH(I1), 1) - WEEKDAY(DATE($D$1, MONTH(I1), 1), 2) + 1 + 3*7 + 6, "") | AO7: =SUM(J7:AN7) | AT7: =IF(AS7>0, AO7/AS7, "")
A8: =WEEKNUM(B8,2) | B8: =IFERROR(DATE($D$1, MONTH(I1), 1) - WEEKDAY(DATE($D$1, MONTH(I1), 1), 2) + 1 + 4*7 + 0, "") | C8: =IFERROR(DATE($D$1, MONTH(I1), 1) - WEEKDAY(DATE($D$1, MONTH(I1), 1), 2) + 1 + 4*7 + 1, "") | D8: =IFERROR(DATE($D$1, MONTH(I1), 1) - WEEKDAY(DATE($D$1, MONTH(I1), 1), 2) + 1 + 4*7 + 2, "") | E8: =IFERROR(DATE($D$1, MONTH(I1), 1) - WEEKDAY(DATE($D$1, MONTH(I1), 1), 2) + 1 + 4*7 + 3, "") | F8: =IFERROR(DATE($D$1, MONTH(I1), 1) - WEEKDAY(DATE($D$1, MONTH(I1), 1), 2) + 1 + 4*7 + 4, "") | G8: =IFERROR(DATE($D$1, MONTH(I1), 1) - WEEKDAY(DATE($D$1, MONTH(I1), 1), 2) + 1 + 4*7 + 5, "") | H8: =IFERROR(DATE($D$1, MONTH(I1), 1) - WEEKDAY(DATE($D$1, MONTH(I1), 1), 2) + 1 + 4*7 + 6, "") | AO8: =SUM(J8:AN8) | AT8: =IF(AS8>0, AO8/AS8, "")
A9: =WEEKNUM(B9,2) | B9: =IFERROR(DATE($D$1, MONTH(I1), 1) - WEEKDAY(DATE($D$1, MONTH(I1), 1), 2) + 1 + 5*7 + 0, "") | C9: =IFERROR(DATE($D$1, MONTH(I1), 1) - WEEKDAY(DATE($D$1, MONTH(I1), 1), 2) + 1 + 5*7 + 1, "") | D9: =IFERROR(DATE($D$1, MONTH(I1), 1) - WEEKDAY(DATE($D$1, MONTH(I1), 1), 2) + 1 + 5*7 + 2, "") | E9: =IFERROR(DATE($D$1, MONTH(I1), 1) - WEEKDAY(DATE($D$1, MONTH(I1), 1), 2) + 1 + 5*7 + 3, "") | F9: =IFERROR(DATE($D$1, MONTH(I1), 1) - WEEKDAY(DATE($D$1, MONTH(I1), 1), 2) + 1 + 5*7 + 4, "") | G9: =IFERROR(DATE($D$1, MONTH(I1), 1) - WEEKDAY(DATE($D$1, MONTH(I1), 1), 2) + 1 + 5*7 + 5, "") | H9: =IFERROR(DATE($D$1, MONTH(I1), 1) - WEEKDAY(DATE($D$1, MONTH(I1), 1), 2) + 1 + 5*7 + 6, "") | AO9: =SUM(J9:AN9) | AT9: =IF(AS9>0, AO9/AS9, "")
AO10: =SUM(J10:AN10) | AT10: =IF(AS10>0, AO10/AS10, "")
AO11: =SUM(J11:AN11) | AT11: =IF(AS11>0, AO11/AS11, "")
AO12: =SUM(J12:AN12) | AT12: =IF(AS12>0, AO12/AS12, "")
AO13: =SUM(J13:AN13) | AT13: =IF(AS13>0, AO13/AS13, "")
AO14: =SUM(J14:AN14) | AT14: =IF(AS14>0, AO14/AS14, "")
AO15: =SUM(J15:AN15) | AT15: =IF(AS15>0, AO15/AS15, "")
AO16: =SUM(J16:AN16) | AT16: =IF(AS16>0, AO16/AS16, "")
AO17: =SUM(J17:AN17) | AT17: =IF(AS17>0, AO17/AS17, "")
AO18: =SUM(J18:AN18) | AT18: =IF(AS18>0, AO18/AS18, "")
AO19: =SUM(J19:AN19) | AT19: =IF(AS19>0, AO19/AS19, "")
AO20: =SUM(J20:AN20) | AT20: =IF(AS20>0, AO20/AS20, "")
AO21: =SUM(J21:AN21) | AT21: =IF(AS21>0, AO21/AS21, "")
AO22: =SUM(J22:AN22) | AT22: =IF(AS22>0, AO22/AS22, "")
A24: 🌬️ | B24: FEBRUARY | I24: =DATE($D$1,2,1) | J24: =I24 | K24: =J24+1 | L24: =K24+1 | M24: =L24+1 | N24: =M24+1 | O24: =N24+1 | P24: =O24+1 | Q24: =P24+1 | R24: =Q24+1 | ... AL24: =AK24+1 | AO24: TOTAL | AQ24: current streak 🔥 | AR24: longest streak😼 | AS24: Goal🔢 | AT24: Progress 📈
J25: =J24 | K25: =K24 | L25: =L24 | M25: =M24 | N25: =N24 | O25: =O24 | P25: =P24 | Q25: =Q24 | ... AL25: =AL24
B26: Пн | C26: Вт | D26: Ср | E26: Чт | F26: Пт | G26: Сб | H26: Вс | I26: =ARRAYFORMULA(Setup!B3:B22) | AO26: =SUM(J26:AN26) | AT26: =IF(AS26>0, AO26/AS26, "")
A27: =WEEKNUM(B27,2) | B27: =IFERROR(DATE($D$1, MONTH(I24), 1) - WEEKDAY(DATE($D$1, MONTH(I24), 1), 2) + 1 + 0*7 + 0, "") | C27: =IFERROR(DATE($D$1, MONTH(I24), 1) - WEEKDAY(DATE($D$1, MONTH(I24), 1), 2) + 1 + 0*7 + 1, "") | D27: =IFERROR(DATE($D$1, MONTH(I24), 1) - WEEKDAY(DATE($D$1, MONTH(I24), 1), 2) + 1 + 0*7 + 2, "") | E27: =IFERROR(DATE($D$1, MONTH(I24), 1) - WEEKDAY(DATE($D$1, MONTH(I24), 1), 2) + 1 + 0*7 + 3, "") | F27: =IFERROR(DATE($D$1, MONTH(I24), 1) - WEEKDAY(DATE($D$1, MONTH(I24), 1), 2) + 1 + 0*7 + 4, "") | G27: =IFERROR(DATE($D$1, MONTH(I24), 1) - WEEKDAY(DATE($D$1, MONTH(I24), 1), 2) + 1 + 0*7 + 5, "") | H27: =IFERROR(DATE($D$1, MONTH(I24), 1) - WEEKDAY(DATE($D$1, MONTH(I24), 1), 2) + 1 + 0*7 + 6, "") | AO27: =SUM(J27:AN27) | AT27: =IF(AS27>0, AO27/AS27, "")
A28: =WEEKNUM(B28,2) | B28: =IFERROR(DATE($D$1, MONTH(I24), 1) - WEEKDAY(DATE($D$1, MONTH(I24), 1), 2) + 1 + 1*7 + 0, "") | C28: =IFERROR(DATE($D$1, MONTH(I24), 1) - WEEKDAY(DATE($D$1, MONTH(I24), 1), 2) + 1 + 1*7 + 1, "") | D28: =IFERROR(DATE($D$1, MONTH(I24), 1) - WEEKDAY(DATE($D$1, MONTH(I24), 1), 2) + 1 + 1*7 + 2, "") | E28: =IFERROR(DATE($D$1, MONTH(I24), 1) - WEEKDAY(DATE($D$1, MONTH(I24), 1), 2) + 1 + 1*7 + 3, "") | F28: =IFERROR(DATE($D$1, MONTH(I24), 1) - WEEKDAY(DATE($D$1, MONTH(I24), 1), 2) + 1 + 1*7 + 4, "") | G28: =IFERROR(DATE($D$1, MONTH(I24), 1) - WEEKDAY(DATE($D$1, MONTH(I24), 1), 2) + 1 + 1*7 + 5, "") | H28: =IFERROR(DATE($D$1, MONTH(I24), 1) - WEEKDAY(DATE($D$1, MONTH(I24), 1), 2) + 1 + 1*7 + 6, "") | AO28: =SUM(J28:AN28) | AT28: =IF(AS28>0, AO28/AS28, "")
A29: =WEEKNUM(B29,2) | B29: =IFERROR(DATE($D$1, MONTH(I24), 1) - WEEKDAY(DATE($D$1, MONTH(I24), 1), 2) + 1 + 2*7 + 0, "") | C29: =IFERROR(DATE($D$1, MONTH(I24), 1) - WEEKDAY(DATE($D$1, MONTH(I24), 1), 2) + 1 + 2*7 + 1, "") | D29: =IFERROR(DATE($D$1, MONTH(I24), 1) - WEEKDAY(DATE($D$1, MONTH(I24), 1), 2) + 1 + 2*7 + 2, "") | E29: =IFERROR(DATE($D$1, MONTH(I24), 1) - WEEKDAY(DATE($D$1, MONTH(I24), 1), 2) + 1 + 2*7 + 3, "") | F29: =IFERROR(DATE($D$1, MONTH(I24), 1) - WEEKDAY(DATE($D$1, MONTH(I24), 1), 2) + 1 + 2*7 + 4, "") | G29: =IFERROR(DATE($D$1, MONTH(I24), 1) - WEEKDAY(DATE($D$1, MONTH(I24), 1), 2) + 1 + 2*7 + 5, "") | H29: =IFERROR(DATE($D$1, MONTH(I24), 1) - WEEKDAY(DATE($D$1, MONTH(I24), 1), 2) + 1 + 2*7 + 6, "") | AO29: =SUM(J29:AN29) | AT29: =IF(AS29>0, AO29/AS29, "")
A30: =WEEKNUM(B30,2) | B30: =IFERROR(DATE($D$1, MONTH(I24), 1) - WEEKDAY(DATE($D$1, MONTH(I24), 1), 2) + 1 + 3*7 + 0, "") | C30: =IFERROR(DATE($D$1, MONTH(I24), 1) - WEEKDAY(DATE($D$1, MONTH(I24), 1), 2) + 1 + 3*7 + 1, "") | D30: =IFERROR(DATE($D$1, MONTH(I24), 1) - WEEKDAY(DATE($D$1, MONTH(I24), 1), 2) + 1 + 3*7 + 2, "") | E30: =IFERROR(DATE($D$1, MONTH(I24), 1) - WEEKDAY(DATE($D$1, MONTH(I24), 1), 2) + 1 + 3*7 + 3, "") | F30: =IFERROR(DATE($D$1, MONTH(I24), 1) - WEEKDAY(DATE($D$1, MONTH(I24), 1), 2) + 1 + 3*7 + 4, "") | G30: =IFERROR(DATE($D$1, MONTH(I24), 1) - WEEKDAY(DATE($D$1, MONTH(I24), 1), 2) + 1 + 3*7 + 5, "") | H30: =IFERROR(DATE($D$1, MONTH(I24), 1) - WEEKDAY(DATE($D$1, MONTH(I24), 1), 2) + 1 + 3*7 + 6, "") | AO30: =SUM(J30:AN30) | AT30: =IF(AS30>0, AO30/AS30, "")
A31: =WEEKNUM(B31,2) | B31: =IFERROR(DATE($D$1, MONTH(I24), 1) - WEEKDAY(DATE($D$1, MONTH(I24), 1), 2) + 1 + 4*7 + 0, "") | C31: =IFERROR(DATE($D$1, MONTH(I24), 1) - WEEKDAY(DATE($D$1, MONTH(I24), 1), 2) + 1 + 4*7 + 1, "") | D31: =IFERROR(DATE($D$1, MONTH(I24), 1) - WEEKDAY(DATE($D$1, MONTH(I24), 1), 2) + 1 + 4*7 + 2, "") | E31: =IFERROR(DATE($D$1, MONTH(I24), 1) - WEEKDAY(DATE($D$1, MONTH(I24), 1), 2) + 1 + 4*7 + 3, "") | F31: =IFERROR(DATE($D$1, MONTH(I24), 1) - WEEKDAY(DATE($D$1, MONTH(I24), 1), 2) + 1 + 4*7 + 4, "") | G31: =IFERROR(DATE($D$1, MONTH(I24), 1) - WEEKDAY(DATE($D$1, MONTH(I24), 1), 2) + 1 + 4*7 + 5, "") | H31: =IFERROR(DATE($D$1, MONTH(I24), 1) - WEEKDAY(DATE($D$1, MONTH(I24), 1), 2) + 1 + 4*7 + 6, "") | AO31: =SUM(J31:AN31) | AT31: =IF(AS31>0, AO31/AS31, "")
A32: =WEEKNUM(B32,2) | B32: =IFERROR(DATE($D$1, MONTH(I24), 1) - WEEKDAY(DATE($D$1, MONTH(I24), 1), 2) + 1 + 5*7 + 0, "") | C32: =IFERROR(DATE($D$1, MONTH(I24), 1) - WEEKDAY(DATE($D$1, MONTH(I24), 1), 2) + 1 + 5*7 + 1, "") | D32: =IFERROR(DATE($D$1, MONTH(I24), 1) - WEEKDAY(DATE($D$1, MONTH(I24), 1), 2) + 1 + 5*7 + 2, "") | E32: =IFERROR(DATE($D$1, MONTH(I24), 1) - WEEKDAY(DATE($D$1, MONTH(I24), 1), 2) + 1 + 5*7 + 3, "") | F32: =IFERROR(DATE($D$1, MONTH(I24), 1) - WEEKDAY(DATE($D$1, MONTH(I24), 1), 2) + 1 + 5*7 + 4, "") | G32: =IFERROR(DATE($D$1, MONTH(I24), 1) - WEEKDAY(DATE($D$1, MONTH(I24), 1), 2) + 1 + 5*7 + 5, "") | H32: =IFERROR(DATE($D$1, MONTH(I24), 1) - WEEKDAY(DATE($D$1, MONTH(I24), 1), 2) + 1 + 5*7 + 6, "") | AO32: =SUM(J32:AN32) | AT32: =IF(AS32>0, AO32/AS32, "")
AO33: =SUM(J33:AN33) | AT33: =IF(AS33>0, AO33/AS33, "")
AO34: =SUM(J34:AN34) | AT34: =IF(AS34>0, AO34/AS34, "")
AO35: =SUM(J35:AN35) | AT35: =IF(AS35>0, AO35/AS35, "")
AO36: =SUM(J36:AN36) | AT36: =IF(AS36>0, AO36/AS36, "")
AO37: =SUM(J37:AN37) | AT37: =IF(AS37>0, AO37/AS37, "")
AO38: =SUM(J38:AN38) | AT38: =IF(AS38>0, AO38/AS38, "")
AO39: =SUM(J39:AN39) | AT39: =IF(AS39>0, AO39/AS39, "")
AO40: =SUM(J40:AN40) | AT40: =IF(AS40>0, AO40/AS40, "")
AO41: =SUM(J41:AN41) | AT41: =IF(AS41>0, AO41/AS41, "")
...

Sheet _meta
A1: key | B1: value
A2: template_version | B2: 2
A3: last_sync_at
A4: notes | B4: Template with unified Habits Tracker view

Sheet raw_trackers
A1: tracker_id | B1: name | C1: type | D1: unit | E1: xp | F1: target_day | G1: active | H1: streak_mode | I1: streak_period | J1: streak_min_value | K1: streak_partial_ok | L1: created_at
A2: 1 | B2: Медитация | C2: binary | E2: 5 | G2: TRUE | H2: activity
A3: 2 | B3: Работа часы | C3: time | E3: 5 | G3: TRUE | H3: activity
A4: 3 | B4: минокс | C4: count | E4: 3 | G4: TRUE | H4: activity
A5: 4 | B5: Тренировки | C5: count | E5: 7 | G5: TRUE | H5: goal

Sheet raw_tracker_goals
A1: tracker_id | B1: period | C1: target
A2: 2 | B2: week | C2: 35
A3: 3 | B3: week | C3: 7
A4: 4 | B4: week | C4: 3

Sheet raw_tracker_logs
A1: log_id | B1: tracker_id | C1: date | D1: value | E1: partial | F1: created_at

Sheet raw_missions
A1: date | B1: text | C1: status | D1: done_def | E1: when_do

Sheet raw_journal
A1: date | B1: text

Sheet summary_daily
A1: date | B1: tracker_id | C1: sum_value | D1: avg_value | E1: tracker_name | F1: type | G1: total_value | H1: target_day | I1: unit | J1: goal_hit | K1: week_start | L1: month_start | M1: year_start
A2: =ARRAYFORMULA(QUERY(raw_tracker_logs!B:D,"select C,B,sum(D),avg(D) where C is not null group by C,B order by C",0)) | E2: =ARRAYFORMULA(IF(B2:B<>"",VLOOKUP(B2:B,raw_trackers!A:B,2,FALSE),"")) | F2: =ARRAYFORMULA(IF(B2:B<>"",VLOOKUP(B2:B,raw_trackers!A:C,3,FALSE),"")) | G2: =ARRAYFORMULA(IF(B2:B<>"",IF(F2:F="scale",D2:D,C2:C),"")) | H2: =ARRAYFORMULA(IF(B2:B<>"",VLOOKUP(B2:B,raw_trackers!A:F,6,FALSE),"")) | I2: =ARRAYFORMULA(IF(B2:B<>"",VLOOKUP(B2:B,raw_trackers!A:D,4,FALSE),"")) | J2: =ARRAYFORMULA(IF(H2:H<>"",IF(G2:G>=H2:H,1,0),"")) | K2: =ARRAYFORMULA(IF(A2:A<>"",A2:A-WEEKDAY(A2:A,2)+1,)) | L2: =ARRAYFORMULA(IF(A2:A<>"",DATE(YEAR(A2:A),MONTH(A2:A),1),)) | M2: =ARRAYFORMULA(IF(A2:A<>"",DATE(YEAR(A2:A),1,1),))

Sheet summary_weekly
A1: week_start | B1: tracker_id | C1: tracker_name | D1: total | E1: target_week | F1: goal_hit
A2: =ARRAYFORMULA(QUERY({summary_daily!K2:K,summary_daily!B2:B,summary_daily!E2:E,summary_daily!G2:G},"select Col1,Col2,Col3,sum(Col4) where Col1 is not null group by Col1,Col2,Col3 order by Col1",0)) | E2: =ARRAYFORMULA(IF(B2:B<>"",IFERROR(VLOOKUP(B2:B&"week",{raw_tracker_goals!A:A&raw_tracker_goals!B:B,raw_tracker_goals!C:C},2,FALSE),""),"")) | F2: =ARRAYFORMULA(IF(E2:E<>"",IF(D2:D>=E2:E,1,0),""))

Sheet summary_monthly
A1: month_start | B1: tracker_id | C1: tracker_name | D1: total | E1: target_month | F1: goal_hit
A2: =ARRAYFORMULA(QUERY({summary_daily!L2:L,summary_daily!B2:B,summary_daily!E2:E,summary_daily!G2:G},"select Col1,Col2,Col3,sum(Col4) where Col1 is not null group by Col1,Col2,Col3 order by Col1",0)) | E2: =ARRAYFORMULA(IF(B2:B<>"",IFERROR(VLOOKUP(B2:B&"month",{raw_tracker_goals!A:A&raw_tracker_goals!B:B,raw_tracker_goals!C:C},2,FALSE),""),"")) | F2: =ARRAYFORMULA(IF(E2:E<>"",IF(D2:D>=E2:E,1,0),""))

Sheet summary_yearly
A1: year_start | B1: tracker_id | C1: tracker_name | D1: total | E1: target_year | F1: goal_hit
A2: =ARRAYFORMULA(QUERY({summary_daily!M2:M,summary_daily!B2:B,summary_daily!E2:E,summary_daily!G2:G},"select Col1,Col2,Col3,sum(Col4) where Col1 is not null group by Col1,Col2,Col3 order by Col1",0)) | E2: =ARRAYFORMULA(IF(B2:B<>"",IFERROR(VLOOKUP(B2:B&"year",{raw_tracker_goals!A:A&raw_tracker_goals!B:B,raw_tracker_goals!C:C},2,FALSE),""),"")) | F2: =ARRAYFORMULA(IF(E2:E<>"",IF(D2:D>=E2:E,1,0),""))

Sheet dashboard
A1: tracker_name | B1: =IF(B2="","",VLOOKUP(B2,raw_trackers!A:B,2,FALSE))
A2: tracker_id
A3: period | B3: day
A5: daily_date | B5: daily_total | D5: week_start | E5: weekly_total | G5: month_start | H5: monthly_total | J5: year_start | K5: yearly_total
A6: =FILTER({summary_daily!A:A,summary_daily!G:G},summary_daily!B:B=$B$2) | D6: =FILTER({summary_weekly!A:A,summary_weekly!D:D},summary_weekly!B:B=$B$2) | G6: =FILTER({summary_monthly!A:A,summary_monthly!D:D},summary_monthly!B:B=$B$2) | J6: =FILTER({summary_yearly!A:A,summary_yearly!D:D},summary_yearly!B:B=$B$2)
