Workbook

Sheet Setup
B2: Write out your own habits here: | D2: Choose emojis | E2: ⤵️⤵️⤵️ | G2: Emoji keyboard shortcut:
B3: 🧘🏻‍♀️Yoga | D3: 0 habits done | G3: 🪟: Press Windows + ; (semi-colon) or Windows + . (period)
B4: 🌜Meditate | D4: 1 habit done | E4: 😶 | G4: 🍏: Control + Command + Spacebar
B5: 🥝Eat Fruit | D5: 2 habits done | E5: 🙂
B6: 🚶🏽‍♀️10k Steps | D6: 3 habits done | E6: 😊
B7: 💦2 L water | D7: 4 habits done | E7: 😍
B8: 🏋🏾‍♂️Gym | D8: 5 habits done | E8: 🚀
D9: 6 habits or more | E9: 🔥

Sheet Habits Tracker 2026
B1: Year: | D1: 2026 | I1: January | J1: {=DATE(D1, MATCH(I1, {"January","February","March","April","May","June","July","August","September","October","November","December"}, 0), 1)} -> 46023 | K1: =J1+1 -> 46024 | L1: =K1+1 -> 46025 | M1: =L1+1 -> 46026 | N1: =M1+1 -> 46027 | O1: =N1+1 -> 46028 | P1: =O1+1 -> 46029 | Q1: =P1+1 -> 46030 | R1: =Q1+1 -> 46031 | ... AN1: =AM1+1 -> 46053 | AO1: TOTAL | AQ1: current streak 🔥 | AR1: longest streak😼 | AS1: Goal🔢 | AT1: Progress 📈
B2: Week start: | E2: Monday | I2: =D1 -> 2026 | J2: =J1 -> 46023 | K2: =K1 -> 46024 | L2: =L1 -> 46025 | M2: =M1 -> 46026 | N2: =N1 -> 46027 | O2: =O1 -> 46028 | P2: =P1 -> 46029 | Q2: =Q1 -> 46030 | ... AN2: =AN1 -> 46053
B3: =IF($E$2="Monday", TEXT(TODAY()-WEEKDAY(TODAY(),2)+COLUMN(B3)-1,"ddd"), TEXT(TODAY()-WEEKDAY(TODAY(),1)+IF(COLUMN(B3)>1,COLUMN(B3)-1,7),"ddd")) -> Mon | C3: =IF($E$2="Monday", TEXT(TODAY()-WEEKDAY(TODAY(),2)+COLUMN(C3)-1,"ddd"), TEXT(TODAY()-WEEKDAY(TODAY(),1)+IF(COLUMN(C3)>1,COLUMN(C3)-1,7),"ddd")) -> Tue | D3: =IF($E$2="Monday", TEXT(TODAY()-WEEKDAY(TODAY(),2)+COLUMN(D3)-1,"ddd"), TEXT(TODAY()-WEEKDAY(TODAY(),1)+IF(COLUMN(D3)>1,COLUMN(D3)-1,7),"ddd")) -> Wed | E3: =IF($E$2="Monday", TEXT(TODAY()-WEEKDAY(TODAY(),2)+COLUMN(E3)-1,"ddd"), TEXT(TODAY()-WEEKDAY(TODAY(),1)+IF(COLUMN(E3)>1,COLUMN(E3)-1,7),"ddd")) -> Thu | F3: =IF($E$2="Monday", TEXT(TODAY()-WEEKDAY(TODAY(),2)+COLUMN(F3)-1,"ddd"), TEXT(TODAY()-WEEKDAY(TODAY(),1)+IF(COLUMN(F3)>1,COLUMN(F3)-1,7),"ddd")) -> Fri | G3: =IF($E$2="Monday", TEXT(TODAY()-WEEKDAY(TODAY(),2)+COLUMN(G3)-1,"ddd"), TEXT(TODAY()-WEEKDAY(TODAY(),1)+IF(COLUMN(G3)>1,COLUMN(G3)-1,7),"ddd")) -> Sat | H3: =IF($E$2="Monday", TEXT(TODAY()-WEEKDAY(TODAY(),2)+COLUMN(H3)-1,"ddd"), TEXT(TODAY()-WEEKDAY(TODAY(),1)+IF(COLUMN(H3)>1,COLUMN(H3)-1,7),"ddd")) -> Sun | I3: {=Setup!$B$3:$B$22} -> 🧘🏻‍♀️Yoga | J3: FALSE | K3: FALSE | L3: FALSE | M3: FALSE | N3: FALSE | O3: FALSE | P3: FALSE | Q3: FALSE | R3: FALSE | S3: FALSE | T3: FALSE | U3: FALSE | V3: FALSE | W3: FALSE | X3: FALSE | Y3: FALSE | Z3: FALSE | AA3: FALSE | AB3: FALSE | AC3: FALSE | AD3: FALSE | AE3: FALSE | AF3: FALSE | AG3: FALSE | AH3: FALSE | AI3: FALSE | AJ3: FALSE | AK3: FALSE | AL3: FALSE | AM3: FALSE | AN3: FALSE | AO3: =COUNTIF(J3:AN3, "TRUE") -> 0 | AQ3: =IFERROR(__xludf.DUMMYFUNCTION("if(iserror(match(true,J3:AN3,0)),0,len(index(split(substitute(substitute(join("","",J3:AN3)&"","",""TRUE,"",""x""),""FALSE,"","",""),"",""),,counta(split(substitute(substitute(join("","",J3:AN3)&"","",""TRUE,"",""x""),""FALSE,"","",""),"","")))))"),0.0) -> 0 | AR3: =IFERROR(__xludf.DUMMYFUNCTION("arrayformula( if( sum(J3:AN3 + 0), max( len( split( concatenate( left(J3:AN3) ), ""F"" ) ) ), ""0"" ) )"),"0") -> 0 | AS3: 8 | AT3: =AO3/AS3 -> 0
A4: =WEEKNUM(DATE(D1, MONTH(I1 & 1), 1), 2) -> 1 | B4: {=IFERROR(DATE($D$1, 1, (A4-1)*7 + 2 - WEEKDAY(DATE($D$1, 1, 1) - MATCH(B3, {"Mon","Tue","Wed","Thu","Fri","Sat","Sun"}, 0))), "")} -> 46020 | C4: =B4+1 -> 46021 | D4: =C4+1 -> 46022 | E4: =D4+1 -> 46023 | F4: =E4+1 -> 46024 | G4: =F4+1 -> 46025 | H4: =G4+1 -> 46026 | I4: 🌜Meditate | J4: FALSE | K4: FALSE | L4: FALSE | M4: FALSE | N4: FALSE | O4: FALSE | P4: FALSE | Q4: FALSE | R4: FALSE | S4: FALSE | T4: FALSE | U4: FALSE | V4: FALSE | W4: FALSE | X4: FALSE | Y4: FALSE | Z4: FALSE | AA4: FALSE | AB4: FALSE | AC4: FALSE | AD4: FALSE | AE4: FALSE | AF4: FALSE | AG4: FALSE | AH4: FALSE | AI4: FALSE | AJ4: FALSE | AK4: FALSE | AL4: FALSE | AM4: FALSE | AN4: FALSE | AO4: =COUNTIF(J4:AN4, "TRUE") -> 0 | AQ4: =IFERROR(__xludf.DUMMYFUNCTION("if(iserror(match(true,J4:AN4,0)),0,len(index(split(substitute(substitute(join("","",J4:AN4)&"","",""TRUE,"",""x""),""FALSE,"","",""),"",""),,counta(split(substitute(substitute(join("","",J4:AN4)&"","",""TRUE,"",""x""),""FALSE,"","",""),"","")))))"),0.0) -> 0 | AR4: =IFERROR(__xludf.DUMMYFUNCTION("arrayformula( if( sum(J4:AN4 + 0), max( len( split( concatenate( left(J4:AN4) ), ""F"" ) ) ), ""0"" ) )"),"0") -> 0 | AS4: 9 | AT4: =AO4/AS4 -> 0
A5: =A4+1 -> 2 | B5: =H4+1 -> 46027 | C5: =B5+1 -> 46028 | D5: =C5+1 -> 46029 | E5: =D5+1 -> 46030 | F5: =E5+1 -> 46031 | G5: =F5+1 -> 46032 | H5: =G5+1 -> 46033 | I5: 🥝Eat Fruit | J5: FALSE | K5: FALSE | L5: FALSE | M5: FALSE | N5: FALSE | O5: FALSE | P5: FALSE | Q5: FALSE | R5: FALSE | S5: FALSE | T5: FALSE | U5: FALSE | V5: FALSE | W5: FALSE | X5: FALSE | Y5: FALSE | Z5: FALSE | AA5: FALSE | AB5: FALSE | AC5: FALSE | AD5: FALSE | AE5: FALSE | AF5: FALSE | AG5: FALSE | AH5: FALSE | AI5: FALSE | AJ5: FALSE | AK5: FALSE | AL5: FALSE | AM5: FALSE | AN5: FALSE | AO5: =COUNTIF(J5:AN5, "TRUE") -> 0 | AQ5: =IFERROR(__xludf.DUMMYFUNCTION("if(iserror(match(true,J5:AN5,0)),0,len(index(split(substitute(substitute(join("","",J5:AN5)&"","",""TRUE,"",""x""),""FALSE,"","",""),"",""),,counta(split(substitute(substitute(join("","",J5:AN5)&"","",""TRUE,"",""x""),""FALSE,"","",""),"","")))))"),0.0) -> 0 | AR5: =IFERROR(__xludf.DUMMYFUNCTION("arrayformula( if( sum(J5:AN5 + 0), max( len( split( concatenate( left(J5:AN5) ), ""F"" ) ) ), ""0"" ) )"),"0") -> 0 | AS5: 10 | AT5: =AO5/AS5 -> 0
A6: =A5+1 -> 3 | B6: =H5+1 -> 46034 | C6: =B6+1 -> 46035 | D6: =C6+1 -> 46036 | E6: =D6+1 -> 46037 | F6: =E6+1 -> 46038 | G6: =F6+1 -> 46039 | H6: =G6+1 -> 46040 | I6: 🚶🏽‍♀️10k Steps | J6: FALSE | K6: FALSE | L6: FALSE | M6: FALSE | N6: FALSE | O6: FALSE | P6: FALSE | Q6: FALSE | R6: FALSE | S6: FALSE | T6: FALSE | U6: FALSE | V6: FALSE | W6: FALSE | X6: FALSE | Y6: FALSE | Z6: FALSE | AA6: FALSE | AB6: FALSE | AC6: FALSE | AD6: FALSE | AE6: FALSE | AF6: FALSE | AG6: FALSE | AH6: FALSE | AI6: FALSE | AJ6: FALSE | AK6: FALSE | AL6: FALSE | AM6: FALSE | AN6: FALSE | AO6: =COUNTIF(J6:AN6, "TRUE") -> 0 | AQ6: =IFERROR(__xludf.DUMMYFUNCTION("if(iserror(match(true,J6:AN6,0)),0,len(index(split(substitute(substitute(join("","",J6:AN6)&"","",""TRUE,"",""x""),""FALSE,"","",""),"",""),,counta(split(substitute(substitute(join("","",J6:AN6)&"","",""TRUE,"",""x""),""FALSE,"","",""),"","")))))"),0.0) -> 0 | AR6: =IFERROR(__xludf.DUMMYFUNCTION("arrayformula( if( sum(J6:AN6 + 0), max( len( split( concatenate( left(J6:AN6) ), ""F"" ) ) ), ""0"" ) )"),"0") -> 0 | AS6: 11 | AT6: =AO6/AS6 -> 0
A7: =A6+1 -> 4 | B7: =H6+1 -> 46041 | C7: =B7+1 -> 46042 | D7: =C7+1 -> 46043 | E7: =D7+1 -> 46044 | F7: =E7+1 -> 46045 | G7: =F7+1 -> 46046 | H7: =G7+1 -> 46047 | I7: 💦2 L water | J7: FALSE | K7: FALSE | L7: FALSE | M7: FALSE | N7: FALSE | O7: FALSE | P7: FALSE | Q7: FALSE | R7: FALSE | S7: FALSE | T7: FALSE | U7: TRUE | V7: FALSE | W7: FALSE | X7: FALSE | Y7: FALSE | Z7: FALSE | AA7: FALSE | AB7: FALSE | AC7: FALSE | AD7: FALSE | AE7: FALSE | AF7: FALSE | AG7: FALSE | AH7: FALSE | AI7: FALSE | AJ7: FALSE | AK7: FALSE | AL7: FALSE | AM7: FALSE | AN7: FALSE | AO7: =COUNTIF(J7:AN7, "TRUE") -> 1 | AQ7: =IFERROR(__xludf.DUMMYFUNCTION("if(iserror(match(true,J7:AN7,0)),0,len(index(split(substitute(substitute(join("","",J7:AN7)&"","",""TRUE,"",""x""),""FALSE,"","",""),"",""),,counta(split(substitute(substitute(join("","",J7:AN7)&"","",""TRUE,"",""x""),""FALSE,"","",""),"","")))))"),1.0) -> 1 | AR7: =IFERROR(__xludf.DUMMYFUNCTION("arrayformula( if( sum(J7:AN7 + 0), max( len( split( concatenate( left(J7:AN7) ), ""F"" ) ) ), ""0"" ) )"),1.0) -> 1 | AS7: 12 | AT7: =AO7/AS7 -> 0.083333333
A8: =A7+1 -> 5 | B8: =H7+1 -> 46048 | C8: =B8+1 -> 46049 | D8: =C8+1 -> 46050 | E8: =D8+1 -> 46051 | F8: =E8+1 -> 46052 | G8: =F8+1 -> 46053 | H8: =G8+1 -> 46054 | I8: 🏋🏾‍♂️Gym | J8: FALSE | K8: FALSE | L8: FALSE | M8: FALSE | N8: FALSE | O8: FALSE | P8: FALSE | Q8: FALSE | R8: FALSE | S8: FALSE | T8: FALSE | U8: FALSE | V8: FALSE | W8: FALSE | X8: FALSE | Y8: FALSE | Z8: FALSE | AA8: FALSE | AB8: FALSE | AC8: FALSE | AD8: FALSE | AE8: FALSE | AF8: FALSE | AG8: FALSE | AH8: FALSE | AI8: FALSE | AJ8: FALSE | AK8: FALSE | AL8: FALSE | AM8: FALSE | AN8: FALSE | AO8: =COUNTIF(J8:AN8, "TRUE") -> 0 | AQ8: =IFERROR(__xludf.DUMMYFUNCTION("if(iserror(match(true,J8:AN8,0)),0,len(index(split(substitute(substitute(join("","",J8:AN8)&"","",""TRUE,"",""x""),""FALSE,"","",""),"",""),,counta(split(substitute(substitute(join("","",J8:AN8)&"","",""TRUE,"",""x""),""FALSE,"","",""),"","")))))"),0.0) -> 0 | AR8: =IFERROR(__xludf.DUMMYFUNCTION("arrayformula( if( sum(J8:AN8 + 0), max( len( split( concatenate( left(J8:AN8) ), ""F"" ) ) ), ""0"" ) )"),"0") -> 0 | AS8: 13 | AT8: =AO8/AS8 -> 0
A9: =A8+1 -> 6 | B9: =H8+1 -> 46055 | C9: =B9+1 -> 46056 | D9: =C9+1 -> 46057 | E9: =D9+1 -> 46058 | F9: =E9+1 -> 46059 | G9: =F9+1 -> 46060 | H9: =G9+1 -> 46061 | J9: FALSE | K9: FALSE | L9: FALSE | M9: FALSE | N9: FALSE | O9: FALSE | P9: FALSE | Q9: FALSE | R9: FALSE | S9: FALSE | T9: FALSE | U9: FALSE | V9: FALSE | W9: FALSE | X9: FALSE | Y9: FALSE | Z9: FALSE | AA9: FALSE | AB9: FALSE | AC9: FALSE | AD9: FALSE | AE9: FALSE | AF9: FALSE | AG9: FALSE | AH9: FALSE | AI9: FALSE | AJ9: FALSE | AK9: FALSE | AL9: FALSE | AM9: FALSE | AN9: FALSE | AO9: =COUNTIF(J9:AN9, "TRUE") -> 0 | AQ9: =IFERROR(__xludf.DUMMYFUNCTION("if(iserror(match(true,J9:AN9,0)),0,len(index(split(substitute(substitute(join("","",J9:AN9)&"","",""TRUE,"",""x""),""FALSE,"","",""),"",""),,counta(split(substitute(substitute(join("","",J9:AN9)&"","",""TRUE,"",""x""),""FALSE,"","",""),"","")))))"),0.0) -> 0 | AR9: =IFERROR(__xludf.DUMMYFUNCTION("arrayformula( if( sum(J9:AN9 + 0), max( len( split( concatenate( left(J9:AN9) ), ""F"" ) ) ), ""0"" ) )"),"0") -> 0 | AS9: 14 | AT9: =AO9/AS9 -> 0
J10: FALSE | K10: FALSE | L10: FALSE | M10: FALSE | N10: FALSE | O10: FALSE | P10: FALSE | Q10: FALSE | R10: FALSE | S10: FALSE | T10: FALSE | U10: FALSE | V10: FALSE | W10: FALSE | X10: FALSE | Y10: FALSE | Z10: FALSE | AA10: FALSE | AB10: FALSE | AC10: FALSE | AD10: FALSE | AE10: FALSE | AF10: FALSE | AG10: FALSE | AH10: FALSE | AI10: FALSE | AJ10: FALSE | AK10: FALSE | AL10: FALSE | AM10: FALSE | AN10: FALSE | AO10: =COUNTIF(J10:AN10, "TRUE") -> 0 | AQ10: =IFERROR(__xludf.DUMMYFUNCTION("if(iserror(match(true,J10:AN10,0)),0,len(index(split(substitute(substitute(join("","",J10:AN10)&"","",""TRUE,"",""x""),""FALSE,"","",""),"",""),,counta(split(substitute(substitute(join("","",J10:AN10)&"","",""TRUE,"",""x""),""FALSE,"","",""),"","")))))"),0.0) -> 0 | AR10: =IFERROR(__xludf.DUMMYFUNCTION("arrayformula( if( sum(J10:AN10 + 0), max( len( split( concatenate( left(J10:AN10) ), ""F"" ) ) ), ""0"" ) )"),"0") -> 0 | AS10: 15 | AT10: =AO10/AS10 -> 0
J11: FALSE | K11: FALSE | L11: FALSE | M11: FALSE | N11: FALSE | O11: FALSE | P11: FALSE | Q11: FALSE | R11: FALSE | S11: FALSE | T11: FALSE | U11: FALSE | V11: FALSE | W11: FALSE | X11: FALSE | Y11: FALSE | Z11: FALSE | AA11: FALSE | AB11: FALSE | AC11: FALSE | AD11: FALSE | AE11: FALSE | AF11: FALSE | AG11: FALSE | AH11: FALSE | AI11: FALSE | AJ11: FALSE | AK11: FALSE | AL11: FALSE | AM11: FALSE | AN11: FALSE | AO11: =COUNTIF(J11:AN11, "TRUE") -> 0 | AQ11: =IFERROR(__xludf.DUMMYFUNCTION("if(iserror(match(true,J11:AN11,0)),0,len(index(split(substitute(substitute(join("","",J11:AN11)&"","",""TRUE,"",""x""),""FALSE,"","",""),"",""),,counta(split(substitute(substitute(join("","",J11:AN11)&"","",""TRUE,"",""x""),""FALSE,"","",""),"","")))))"),0.0) -> 0 | AR11: =IFERROR(__xludf.DUMMYFUNCTION("arrayformula( if( sum(J11:AN11 + 0), max( len( split( concatenate( left(J11:AN11) ), ""F"" ) ) ), ""0"" ) )"),"0") -> 0 | AS11: 15 | AT11: =AO11/AS11 -> 0
J12: FALSE | K12: FALSE | L12: FALSE | M12: FALSE | N12: FALSE | O12: FALSE | P12: FALSE | Q12: FALSE | R12: FALSE | S12: FALSE | T12: FALSE | U12: FALSE | V12: FALSE | W12: FALSE | X12: FALSE | Y12: FALSE | Z12: FALSE | AA12: FALSE | AB12: FALSE | AC12: FALSE | AD12: FALSE | AE12: FALSE | AF12: FALSE | AG12: FALSE | AH12: FALSE | AI12: FALSE | AJ12: FALSE | AK12: FALSE | AL12: FALSE | AM12: FALSE | AN12: FALSE | AO12: =COUNTIF(J12:AN12, "TRUE") -> 0 | AQ12: =IFERROR(__xludf.DUMMYFUNCTION("if(iserror(match(true,J12:AN12,0)),0,len(index(split(substitute(substitute(join("","",J12:AN12)&"","",""TRUE,"",""x""),""FALSE,"","",""),"",""),,counta(split(substitute(substitute(join("","",J12:AN12)&"","",""TRUE,"",""x""),""FALSE,"","",""),"","")))))"),0.0) -> 0 | AR12: =IFERROR(__xludf.DUMMYFUNCTION("arrayformula( if( sum(J12:AN12 + 0), max( len( split( concatenate( left(J12:AN12) ), ""F"" ) ) ), ""0"" ) )"),"0") -> 0 | AS12: 15 | AT12: =AO12/AS12 -> 0
J13: FALSE | K13: FALSE | L13: FALSE | M13: FALSE | N13: FALSE | O13: FALSE | P13: FALSE | Q13: FALSE | R13: FALSE | S13: FALSE | T13: FALSE | U13: FALSE | V13: FALSE | W13: FALSE | X13: FALSE | Y13: FALSE | Z13: FALSE | AA13: FALSE | AB13: FALSE | AC13: FALSE | AD13: FALSE | AE13: FALSE | AF13: FALSE | AG13: FALSE | AH13: FALSE | AI13: FALSE | AJ13: FALSE | AK13: FALSE | AL13: FALSE | AM13: FALSE | AN13: FALSE | AO13: =COUNTIF(J13:AN13, "TRUE") -> 0 | AQ13: =IFERROR(__xludf.DUMMYFUNCTION("if(iserror(match(true,J13:AN13,0)),0,len(index(split(substitute(substitute(join("","",J13:AN13)&"","",""TRUE,"",""x""),""FALSE,"","",""),"",""),,counta(split(substitute(substitute(join("","",J13:AN13)&"","",""TRUE,"",""x""),""FALSE,"","",""),"","")))))"),0.0) -> 0 | AR13: =IFERROR(__xludf.DUMMYFUNCTION("arrayformula( if( sum(J13:AN13 + 0), max( len( split( concatenate( left(J13:AN13) ), ""F"" ) ) ), ""0"" ) )"),"0") -> 0 | AS13: 15 | AT13: =AO13/AS13 -> 0
J14: FALSE | K14: FALSE | L14: FALSE | M14: FALSE | N14: FALSE | O14: FALSE | P14: FALSE | Q14: FALSE | R14: FALSE | S14: FALSE | T14: FALSE | U14: FALSE | V14: FALSE | W14: FALSE | X14: FALSE | Y14: FALSE | Z14: FALSE | AA14: FALSE | AB14: FALSE | AC14: FALSE | AD14: FALSE | AE14: FALSE | AF14: FALSE | AG14: FALSE | AH14: FALSE | AI14: FALSE | AJ14: FALSE | AK14: FALSE | AL14: FALSE | AM14: FALSE | AN14: FALSE | AO14: =COUNTIF(J14:AN14, "TRUE") -> 0 | AQ14: =IFERROR(__xludf.DUMMYFUNCTION("if(iserror(match(true,J14:AN14,0)),0,len(index(split(substitute(substitute(join("","",J14:AN14)&"","",""TRUE,"",""x""),""FALSE,"","",""),"",""),,counta(split(substitute(substitute(join("","",J14:AN14)&"","",""TRUE,"",""x""),""FALSE,"","",""),"","")))))"),0.0) -> 0 | AR14: =IFERROR(__xludf.DUMMYFUNCTION("arrayformula( if( sum(J14:AN14 + 0), max( len( split( concatenate( left(J14:AN14) ), ""F"" ) ) ), ""0"" ) )"),"0") -> 0 | AS14: 15 | AT14: =AO14/AS14 -> 0
J15: FALSE | K15: FALSE | L15: FALSE | M15: FALSE | N15: FALSE | O15: FALSE | P15: FALSE | Q15: FALSE | R15: FALSE | S15: FALSE | T15: FALSE | U15: FALSE | V15: FALSE | W15: FALSE | X15: FALSE | Y15: FALSE | Z15: FALSE | AA15: FALSE | AB15: FALSE | AC15: FALSE | AD15: FALSE | AE15: FALSE | AF15: FALSE | AG15: FALSE | AH15: FALSE | AI15: FALSE | AJ15: FALSE | AK15: FALSE | AL15: FALSE | AM15: FALSE | AN15: FALSE | AO15: =COUNTIF(J15:AN15, "TRUE") -> 0 | AQ15: =IFERROR(__xludf.DUMMYFUNCTION("if(iserror(match(true,J15:AN15,0)),0,len(index(split(substitute(substitute(join("","",J15:AN15)&"","",""TRUE,"",""x""),""FALSE,"","",""),"",""),,counta(split(substitute(substitute(join("","",J15:AN15)&"","",""TRUE,"",""x""),""FALSE,"","",""),"","")))))"),0.0) -> 0 | AR15: =IFERROR(__xludf.DUMMYFUNCTION("arrayformula( if( sum(J15:AN15 + 0), max( len( split( concatenate( left(J15:AN15) ), ""F"" ) ) ), ""0"" ) )"),"0") -> 0 | AS15: 15 | AT15: =AO15/AS15 -> 0
J16: FALSE | K16: FALSE | L16: FALSE | M16: FALSE | N16: FALSE | O16: FALSE | P16: FALSE | Q16: FALSE | R16: FALSE | S16: FALSE | T16: FALSE | U16: FALSE | V16: FALSE | W16: FALSE | X16: FALSE | Y16: FALSE | Z16: FALSE | AA16: FALSE | AB16: FALSE | AC16: FALSE | AD16: FALSE | AE16: FALSE | AF16: FALSE | AG16: FALSE | AH16: FALSE | AI16: FALSE | AJ16: FALSE | AK16: FALSE | AL16: FALSE | AM16: FALSE | AN16: FALSE | AO16: =COUNTIF(J16:AN16, "TRUE") -> 0 | AQ16: =IFERROR(__xludf.DUMMYFUNCTION("if(iserror(match(true,J16:AN16,0)),0,len(index(split(substitute(substitute(join("","",J16:AN16)&"","",""TRUE,"",""x""),""FALSE,"","",""),"",""),,counta(split(substitute(substitute(join("","",J16:AN16)&"","",""TRUE,"",""x""),""FALSE,"","",""),"","")))))"),0.0) -> 0 | AR16: =IFERROR(__xludf.DUMMYFUNCTION("arrayformula( if( sum(J16:AN16 + 0), max( len( split( concatenate( left(J16:AN16) ), ""F"" ) ) ), ""0"" ) )"),"0") -> 0 | AS16: 15 | AT16: =AO16/AS16 -> 0
J17: FALSE | K17: FALSE | L17: FALSE | M17: FALSE | N17: FALSE | O17: FALSE | P17: FALSE | Q17: FALSE | R17: FALSE | S17: FALSE | T17: FALSE | U17: FALSE | V17: FALSE | W17: FALSE | X17: FALSE | Y17: FALSE | Z17: FALSE | AA17: FALSE | AB17: FALSE | AC17: FALSE | AD17: FALSE | AE17: FALSE | AF17: FALSE | AG17: FALSE | AH17: FALSE | AI17: FALSE | AJ17: FALSE | AK17: FALSE | AL17: FALSE | AM17: FALSE | AN17: FALSE | AO17: =COUNTIF(J17:AN17, "TRUE") -> 0 | AQ17: =IFERROR(__xludf.DUMMYFUNCTION("if(iserror(match(true,J17:AN17,0)),0,len(index(split(substitute(substitute(join("","",J17:AN17)&"","",""TRUE,"",""x""),""FALSE,"","",""),"",""),,counta(split(substitute(substitute(join("","",J17:AN17)&"","",""TRUE,"",""x""),""FALSE,"","",""),"","")))))"),0.0) -> 0 | AR17: =IFERROR(__xludf.DUMMYFUNCTION("arrayformula( if( sum(J17:AN17 + 0), max( len( split( concatenate( left(J17:AN17) ), ""F"" ) ) ), ""0"" ) )"),"0") -> 0 | AS17: 15 | AT17: =AO17/AS17 -> 0
J18: FALSE | K18: FALSE | L18: FALSE | M18: FALSE | N18: FALSE | O18: FALSE | P18: FALSE | Q18: FALSE | R18: FALSE | S18: FALSE | T18: FALSE | U18: FALSE | V18: FALSE | W18: FALSE | X18: FALSE | Y18: FALSE | Z18: FALSE | AA18: FALSE | AB18: FALSE | AC18: FALSE | AD18: FALSE | AE18: FALSE | AF18: FALSE | AG18: FALSE | AH18: FALSE | AI18: FALSE | AJ18: FALSE | AK18: FALSE | AL18: FALSE | AM18: FALSE | AN18: FALSE | AO18: =COUNTIF(J18:AN18, "TRUE") -> 0 | AQ18: =IFERROR(__xludf.DUMMYFUNCTION("if(iserror(match(true,J18:AN18,0)),0,len(index(split(substitute(substitute(join("","",J18:AN18)&"","",""TRUE,"",""x""),""FALSE,"","",""),"",""),,counta(split(substitute(substitute(join("","",J18:AN18)&"","",""TRUE,"",""x""),""FALSE,"","",""),"","")))))"),0.0) -> 0 | AR18: =IFERROR(__xludf.DUMMYFUNCTION("arrayformula( if( sum(J18:AN18 + 0), max( len( split( concatenate( left(J18:AN18) ), ""F"" ) ) ), ""0"" ) )"),"0") -> 0 | AS18: 15 | AT18: =AO18/AS18 -> 0
J19: FALSE | K19: FALSE | L19: FALSE | M19: FALSE | N19: FALSE | O19: FALSE | P19: FALSE | Q19: FALSE | R19: FALSE | S19: FALSE | T19: FALSE | U19: FALSE | V19: FALSE | W19: FALSE | X19: FALSE | Y19: FALSE | Z19: FALSE | AA19: FALSE | AB19: FALSE | AC19: FALSE | AD19: FALSE | AE19: FALSE | AF19: FALSE | AG19: FALSE | AH19: FALSE | AI19: FALSE | AJ19: FALSE | AK19: FALSE | AL19: FALSE | AM19: FALSE | AN19: FALSE | AO19: =COUNTIF(J19:AN19, "TRUE") -> 0 | AQ19: =IFERROR(__xludf.DUMMYFUNCTION("if(iserror(match(true,J19:AN19,0)),0,len(index(split(substitute(substitute(join("","",J19:AN19)&"","",""TRUE,"",""x""),""FALSE,"","",""),"",""),,counta(split(substitute(substitute(join("","",J19:AN19)&"","",""TRUE,"",""x""),""FALSE,"","",""),"","")))))"),0.0) -> 0 | AR19: =IFERROR(__xludf.DUMMYFUNCTION("arrayformula( if( sum(J19:AN19 + 0), max( len( split( concatenate( left(J19:AN19) ), ""F"" ) ) ), ""0"" ) )"),"0") -> 0 | AS19: 15 | AT19: =AO19/AS19 -> 0
J20: FALSE | K20: FALSE | L20: FALSE | M20: FALSE | N20: FALSE | O20: FALSE | P20: FALSE | Q20: FALSE | R20: FALSE | S20: FALSE | T20: FALSE | U20: FALSE | V20: FALSE | W20: FALSE | X20: FALSE | Y20: FALSE | Z20: FALSE | AA20: FALSE | AB20: FALSE | AC20: FALSE | AD20: FALSE | AE20: FALSE | AF20: FALSE | AG20: FALSE | AH20: FALSE | AI20: FALSE | AJ20: FALSE | AK20: FALSE | AL20: FALSE | AM20: FALSE | AN20: FALSE | AO20: =COUNTIF(J20:AN20, "TRUE") -> 0 | AQ20: =IFERROR(__xludf.DUMMYFUNCTION("if(iserror(match(true,J20:AN20,0)),0,len(index(split(substitute(substitute(join("","",J20:AN20)&"","",""TRUE,"",""x""),""FALSE,"","",""),"",""),,counta(split(substitute(substitute(join("","",J20:AN20)&"","",""TRUE,"",""x""),""FALSE,"","",""),"","")))))"),0.0) -> 0 | AR20: =IFERROR(__xludf.DUMMYFUNCTION("arrayformula( if( sum(J20:AN20 + 0), max( len( split( concatenate( left(J20:AN20) ), ""F"" ) ) ), ""0"" ) )"),"0") -> 0 | AS20: 15 | AT20: =AO20/AS20 -> 0
J21: FALSE | K21: FALSE | L21: FALSE | M21: FALSE | N21: FALSE | O21: FALSE | P21: FALSE | Q21: FALSE | R21: FALSE | S21: FALSE | T21: FALSE | U21: FALSE | V21: FALSE | W21: FALSE | X21: FALSE | Y21: FALSE | Z21: FALSE | AA21: FALSE | AB21: FALSE | AC21: FALSE | AD21: FALSE | AE21: FALSE | AF21: FALSE | AG21: FALSE | AH21: FALSE | AI21: FALSE | AJ21: FALSE | AK21: FALSE | AL21: FALSE | AM21: FALSE | AN21: FALSE | AO21: =COUNTIF(J21:AN21, "TRUE") -> 0 | AQ21: =IFERROR(__xludf.DUMMYFUNCTION("if(iserror(match(true,J21:AN21,0)),0,len(index(split(substitute(substitute(join("","",J21:AN21)&"","",""TRUE,"",""x""),""FALSE,"","",""),"",""),,counta(split(substitute(substitute(join("","",J21:AN21)&"","",""TRUE,"",""x""),""FALSE,"","",""),"","")))))"),0.0) -> 0 | AR21: =IFERROR(__xludf.DUMMYFUNCTION("arrayformula( if( sum(J21:AN21 + 0), max( len( split( concatenate( left(J21:AN21) ), ""F"" ) ) ), ""0"" ) )"),"0") -> 0 | AS21: 15 | AT21: =AO21/AS21 -> 0
J22: FALSE | K22: FALSE | L22: FALSE | M22: FALSE | N22: FALSE | O22: FALSE | P22: FALSE | Q22: FALSE | R22: FALSE | S22: FALSE | T22: FALSE | U22: FALSE | V22: FALSE | W22: FALSE | X22: FALSE | Y22: FALSE | Z22: FALSE | AA22: FALSE | AB22: FALSE | AC22: FALSE | AD22: FALSE | AE22: FALSE | AF22: FALSE | AG22: FALSE | AH22: FALSE | AI22: FALSE | AJ22: FALSE | AK22: FALSE | AL22: FALSE | AM22: FALSE | AN22: FALSE | AO22: =COUNTIF(J22:AN22, "TRUE") -> 0 | AQ22: =IFERROR(__xludf.DUMMYFUNCTION("if(iserror(match(true,J22:AN22,0)),0,len(index(split(substitute(substitute(join("","",J22:AN22)&"","",""TRUE,"",""x""),""FALSE,"","",""),"",""),,counta(split(substitute(substitute(join("","",J22:AN22)&"","",""TRUE,"",""x""),""FALSE,"","",""),"","")))))"),0.0) -> 0 | AR22: =IFERROR(__xludf.DUMMYFUNCTION("arrayformula( if( sum(J22:AN22 + 0), max( len( split( concatenate( left(J22:AN22) ), ""F"" ) ) ), ""0"" ) )"),"0") -> 0 | AS22: 15 | AT22: =AO22/AS22 -> 0
J23: {=IF(COUNTIF(J3:J22, "TRUE") = 1, Setup!$E$4, IF(COUNTIF(J3:J22, "TRUE") = 0, Setup!$E$3, IF(COUNTIF(J3:J22, "TRUE") = 2, Setup!$E$5, IF(COUNTIF(J3:J22, "TRUE") = 3, Setup!$E$6, IF(COUNTIF(J3:J22, "TRUE") = 4, Setup!$E$7, IF(COUNTIF(J3:J22, "TRUE") = 5, Setup!$E$8, IF(COUNTIF(J3:J22, "TRUE") >= 6, Setup!$E$9))) ))))} | K23: {=IF(COUNTIF(K3:K22, "TRUE") = 1, Setup!$E$4, IF(COUNTIF(K3:K22, "TRUE") = 0, Setup!$E$3, IF(COUNTIF(K3:K22, "TRUE") = 2, Setup!$E$5, IF(COUNTIF(K3:K22, "TRUE") = 3, Setup!$E$6, IF(COUNTIF(K3:K22, "TRUE") = 4, Setup!$E$7, IF(COUNTIF(K3:K22, "TRUE") = 5, Setup!$E$8, IF(COUNTIF(K3:K22, "TRUE") >= 6, Setup!$E$9))) ))))} | L23: {=IF(COUNTIF(L3:L22, "TRUE") = 1, Setup!$E$4, IF(COUNTIF(L3:L22, "TRUE") = 0, Setup!$E$3, IF(COUNTIF(L3:L22, "TRUE") = 2, Setup!$E$5, IF(COUNTIF(L3:L22, "TRUE") = 3, Setup!$E$6, IF(COUNTIF(L3:L22, "TRUE") = 4, Setup!$E$7, IF(COUNTIF(L3:L22, "TRUE") = 5, Setup!$E$8, IF(COUNTIF(L3:L22, "TRUE") >= 6, Setup!$E$9))) ))))} | M23: {=IF(COUNTIF(M3:M22, "TRUE") = 1, Setup!$E$4, IF(COUNTIF(M3:M22, "TRUE") = 0, Setup!$E$3, IF(COUNTIF(M3:M22, "TRUE") = 2, Setup!$E$5, IF(COUNTIF(M3:M22, "TRUE") = 3, Setup!$E$6, IF(COUNTIF(M3:M22, "TRUE") = 4, Setup!$E$7, IF(COUNTIF(M3:M22, "TRUE") = 5, Setup!$E$8, IF(COUNTIF(M3:M22, "TRUE") >= 6, Setup!$E$9))) ))))} | N23: {=IF(COUNTIF(N3:N22, "TRUE") = 1, Setup!$E$4, IF(COUNTIF(N3:N22, "TRUE") = 0, Setup!$E$3, IF(COUNTIF(N3:N22, "TRUE") = 2, Setup!$E$5, IF(COUNTIF(N3:N22, "TRUE") = 3, Setup!$E$6, IF(COUNTIF(N3:N22, "TRUE") = 4, Setup!$E$7, IF(COUNTIF(N3:N22, "TRUE") = 5, Setup!$E$8, IF(COUNTIF(N3:N22, "TRUE") >= 6, Setup!$E$9))) ))))} | O23: {=IF(COUNTIF(O3:O22, "TRUE") = 1, Setup!$E$4, IF(COUNTIF(O3:O22, "TRUE") = 0, Setup!$E$3, IF(COUNTIF(O3:O22, "TRUE") = 2, Setup!$E$5, IF(COUNTIF(O3:O22, "TRUE") = 3, Setup!$E$6, IF(COUNTIF(O3:O22, "TRUE") = 4, Setup!$E$7, IF(COUNTIF(O3:O22, "TRUE") = 5, Setup!$E$8, IF(COUNTIF(O3:O22, "TRUE") >= 6, Setup!$E$9))) ))))} | P23: {=IF(COUNTIF(P3:P22, "TRUE") = 1, Setup!$E$4, IF(COUNTIF(P3:P22, "TRUE") = 0, Setup!$E$3, IF(COUNTIF(P3:P22, "TRUE") = 2, Setup!$E$5, IF(COUNTIF(P3:P22, "TRUE") = 3, Setup!$E$6, IF(COUNTIF(P3:P22, "TRUE") = 4, Setup!$E$7, IF(COUNTIF(P3:P22, "TRUE") = 5, Setup!$E$8, IF(COUNTIF(P3:P22, "TRUE") >= 6, Setup!$E$9))) ))))} | Q23: {=IF(COUNTIF(Q3:Q22, "TRUE") = 1, Setup!$E$4, IF(COUNTIF(Q3:Q22, "TRUE") = 0, Setup!$E$3, IF(COUNTIF(Q3:Q22, "TRUE") = 2, Setup!$E$5, IF(COUNTIF(Q3:Q22, "TRUE") = 3, Setup!$E$6, IF(COUNTIF(Q3:Q22, "TRUE") = 4, Setup!$E$7, IF(COUNTIF(Q3:Q22, "TRUE") = 5, Setup!$E$8, IF(COUNTIF(Q3:Q22, "TRUE") >= 6, Setup!$E$9))) ))))} | ... AN23: {=IF(COUNTIF(AN3:AN22, "TRUE") = 1, Setup!$E$4, IF(COUNTIF(AN3:AN22, "TRUE") = 0, Setup!$E$3, IF(COUNTIF(AN3:AN22, "TRUE") = 2, Setup!$E$5, IF(COUNTIF(AN3:AN22, "TRUE") = 3, Setup!$E$6, IF(COUNTIF(AN3:AN22, "TRUE") = 4, Setup!$E$7, IF(COUNTIF(AN3:AN22, "TRUE") = 5, Setup!$E$8, IF(COUNTIF(AN3:AN22, "TRUE") >= 6, Setup!$E$9))) ))))}
A24: 🌬️ | B24: FEBRUARY | I24: February | J24: {=DATE($D$1, MATCH(I24, {"January","February","March","April","May","June","July","August","September","October","November","December"}, 0), 1)} -> 46054 | K24: =J24+1 -> 46055 | L24: =K24+1 -> 46056 | M24: =L24+1 -> 46057 | N24: =M24+1 -> 46058 | O24: =N24+1 -> 46059 | P24: =O24+1 -> 46060 | Q24: =P24+1 -> 46061 | R24: =Q24+1 -> 46062 | ... AL24: =AK24+1 -> 46082 | AO24: TOTAL | AQ24: current streak 🔥 | AR24: longest streak😼 | AS24: Goal🔢 | AT24: Progress 📈
J25: =J24 -> 46054 | K25: =K24 -> 46055 | L25: =L24 -> 46056 | M25: =M24 -> 46057 | N25: =N24 -> 46058 | O25: =O24 -> 46059 | P25: =P24 -> 46060 | Q25: =Q24 -> 46061 | ... AL25: =AL24 -> 46082
B26: =IF($E$2="Monday", TEXT(TODAY()-WEEKDAY(TODAY(),2)+COLUMN(B26)-1,"ddd"), TEXT(TODAY()-WEEKDAY(TODAY(),1)+IF(COLUMN(B26)>1,COLUMN(B26)-1,7),"ddd")) -> Mon | C26: =IF($E$2="Monday", TEXT(TODAY()-WEEKDAY(TODAY(),2)+COLUMN(C26)-1,"ddd"), TEXT(TODAY()-WEEKDAY(TODAY(),1)+IF(COLUMN(C26)>1,COLUMN(C26)-1,7),"ddd")) -> Tue | D26: =IF($E$2="Monday", TEXT(TODAY()-WEEKDAY(TODAY(),2)+COLUMN(D26)-1,"ddd"), TEXT(TODAY()-WEEKDAY(TODAY(),1)+IF(COLUMN(D26)>1,COLUMN(D26)-1,7),"ddd")) -> Wed | E26: =IF($E$2="Monday", TEXT(TODAY()-WEEKDAY(TODAY(),2)+COLUMN(E26)-1,"ddd"), TEXT(TODAY()-WEEKDAY(TODAY(),1)+IF(COLUMN(E26)>1,COLUMN(E26)-1,7),"ddd")) -> Thu | F26: =IF($E$2="Monday", TEXT(TODAY()-WEEKDAY(TODAY(),2)+COLUMN(F26)-1,"ddd"), TEXT(TODAY()-WEEKDAY(TODAY(),1)+IF(COLUMN(F26)>1,COLUMN(F26)-1,7),"ddd")) -> Fri | G26: =IF($E$2="Monday", TEXT(TODAY()-WEEKDAY(TODAY(),2)+COLUMN(G26)-1,"ddd"), TEXT(TODAY()-WEEKDAY(TODAY(),1)+IF(COLUMN(G26)>1,COLUMN(G26)-1,7),"ddd")) -> Sat | H26: =IF($E$2="Monday", TEXT(TODAY()-WEEKDAY(TODAY(),2)+COLUMN(H26)-1,"ddd"), TEXT(TODAY()-WEEKDAY(TODAY(),1)+IF(COLUMN(H26)>1,COLUMN(H26)-1,7),"ddd")) -> Sun | I26: {=Setup!$B$3:$B$22} -> 🧘🏻‍♀️Yoga | J26: FALSE | K26: FALSE | L26: FALSE | M26: FALSE | N26: FALSE | O26: FALSE | P26: FALSE | Q26: FALSE | R26: FALSE | S26: FALSE | T26: FALSE | U26: FALSE | V26: FALSE | W26: FALSE | X26: FALSE | Y26: FALSE | Z26: FALSE | AA26: FALSE | AB26: FALSE | AC26: FALSE | AD26: FALSE | AE26: FALSE | AF26: FALSE | AG26: FALSE | AH26: FALSE | AI26: FALSE | AJ26: FALSE | AK26: FALSE | AL26: FALSE | AO26: =COUNTIF(J26:AN26, "TRUE") -> 0 | AQ26: =IFERROR(__xludf.DUMMYFUNCTION("if(iserror(match(true,J26:AN26,0)),0,len(index(split(substitute(substitute(join("","",J26:AN26)&"","",""TRUE,"",""x""),""FALSE,"","",""),"",""),,counta(split(substitute(substitute(join("","",J26:AN26)&"","",""TRUE,"",""x""),""FALSE,"","",""),"","")))))"),0.0) -> 0 | AR26: =IFERROR(__xludf.DUMMYFUNCTION("arrayformula( if( sum(J26:AN26 + 0), max( len( split( concatenate( left(J26:AN26) ), ""F"" ) ) ), ""0"" ) )"),"0") -> 0 | AS26: 15 | AT26: =AO26/AS26 -> 0
A27: =WEEKNUM(DATE(D1, MONTH(I24 & 1), 1), 2) -> 5 | B27: {=IFERROR(DATE($D$1, 1, (A27-1)*7 + 2 - WEEKDAY(DATE($D$1, 1, 1) - MATCH(B26, {"Mon","Tue","Wed","Thu","Fri","Sat","Sun"}, 0))), "")} -> 46048 | C27: =B27+1 -> 46049 | D27: =C27+1 -> 46050 | E27: =D27+1 -> 46051 | F27: =E27+1 -> 46052 | G27: =F27+1 -> 46053 | H27: =G27+1 -> 46054 | I27: 🌜Meditate | J27: FALSE | K27: FALSE | L27: FALSE | M27: FALSE | N27: FALSE | O27: FALSE | P27: FALSE | Q27: FALSE | R27: FALSE | S27: FALSE | T27: FALSE | U27: FALSE | V27: FALSE | W27: FALSE | X27: FALSE | Y27: FALSE | Z27: FALSE | AA27: FALSE | AB27: FALSE | AC27: FALSE | AD27: FALSE | AE27: FALSE | AF27: FALSE | AG27: FALSE | AH27: FALSE | AI27: FALSE | AJ27: FALSE | AK27: FALSE | AL27: FALSE | AO27: =COUNTIF(J27:AN27, "TRUE") -> 0 | AQ27: =IFERROR(__xludf.DUMMYFUNCTION("if(iserror(match(true,J27:AN27,0)),0,len(index(split(substitute(substitute(join("","",J27:AN27)&"","",""TRUE,"",""x""),""FALSE,"","",""),"",""),,counta(split(substitute(substitute(join("","",J27:AN27)&"","",""TRUE,"",""x""),""FALSE,"","",""),"","")))))"),0.0) -> 0 | AR27: =IFERROR(__xludf.DUMMYFUNCTION("arrayformula( if( sum(J27:AN27 + 0), max( len( split( concatenate( left(J27:AN27) ), ""F"" ) ) ), ""0"" ) )"),"0") -> 0 | AS27: 20 | AT27: =AO27/AS27 -> 0
A28: =A27+1 -> 6 | B28: =H27+1 -> 46055 | C28: =B28+1 -> 46056 | D28: =C28+1 -> 46057 | E28: =D28+1 -> 46058 | F28: =E28+1 -> 46059 | G28: =F28+1 -> 46060 | H28: =G28+1 -> 46061 | I28: 🥝Eat Fruit | J28: FALSE | K28: FALSE | L28: FALSE | M28: FALSE | N28: FALSE | O28: FALSE | P28: FALSE | Q28: FALSE | R28: FALSE | S28: FALSE | T28: FALSE | U28: FALSE | V28: FALSE | W28: FALSE | X28: FALSE | Y28: FALSE | Z28: FALSE | AA28: FALSE | AB28: FALSE | AC28: FALSE | AD28: FALSE | AE28: FALSE | AF28: FALSE | AG28: FALSE | AH28: FALSE | AI28: FALSE | AJ28: FALSE | AK28: FALSE | AL28: FALSE | AO28: =COUNTIF(J28:AN28, "TRUE") -> 0 | AQ28: =IFERROR(__xludf.DUMMYFUNCTION("if(iserror(match(true,J28:AN28,0)),0,len(index(split(substitute(substitute(join("","",J28:AN28)&"","",""TRUE,"",""x""),""FALSE,"","",""),"",""),,counta(split(substitute(substitute(join("","",J28:AN28)&"","",""TRUE,"",""x""),""FALSE,"","",""),"","")))))"),0.0) -> 0 | AR28: =IFERROR(__xludf.DUMMYFUNCTION("arrayformula( if( sum(J28:AN28 + 0), max( len( split( concatenate( left(J28:AN28) ), ""F"" ) ) ), ""0"" ) )"),"0") -> 0 | AS28: 30 | AT28: =AO28/AS28 -> 0
A29: =A28+1 -> 7 | B29: =H28+1 -> 46062 | C29: =B29+1 -> 46063 | D29: =C29+1 -> 46064 | E29: =D29+1 -> 46065 | F29: =E29+1 -> 46066 | G29: =F29+1 -> 46067 | H29: =G29+1 -> 46068 | I29: 🚶🏽‍♀️10k Steps | J29: FALSE | K29: FALSE | L29: FALSE | M29: FALSE | N29: FALSE | O29: FALSE | P29: FALSE | Q29: FALSE | R29: FALSE | S29: FALSE | T29: FALSE | U29: FALSE | V29: FALSE | W29: FALSE | X29: FALSE | Y29: FALSE | Z29: FALSE | AA29: FALSE | AB29: FALSE | AC29: FALSE | AD29: FALSE | AE29: FALSE | AF29: FALSE | AG29: FALSE | AH29: FALSE | AI29: FALSE | AJ29: FALSE | AK29: FALSE | AL29: FALSE | AO29: =COUNTIF(J29:AN29, "TRUE") -> 0 | AQ29: =IFERROR(__xludf.DUMMYFUNCTION("if(iserror(match(true,J29:AN29,0)),0,len(index(split(substitute(substitute(join("","",J29:AN29)&"","",""TRUE,"",""x""),""FALSE,"","",""),"",""),,counta(split(substitute(substitute(join("","",J29:AN29)&"","",""TRUE,"",""x""),""FALSE,"","",""),"","")))))"),0.0) -> 0 | AR29: =IFERROR(__xludf.DUMMYFUNCTION("arrayformula( if( sum(J29:AN29 + 0), max( len( split( concatenate( left(J29:AN29) ), ""F"" ) ) ), ""0"" ) )"),"0") -> 0 | AS29: 20 | AT29: =AO29/AS29 -> 0
A30: =A29+1 -> 8 | B30: =H29+1 -> 46069 | C30: =B30+1 -> 46070 | D30: =C30+1 -> 46071 | E30: =D30+1 -> 46072 | F30: =E30+1 -> 46073 | G30: =F30+1 -> 46074 | H30: =G30+1 -> 46075 | I30: 💦2 L water | J30: FALSE | K30: FALSE | L30: FALSE | M30: FALSE | N30: FALSE | O30: FALSE | P30: FALSE | Q30: FALSE | R30: FALSE | S30: FALSE | T30: FALSE | U30: FALSE | V30: FALSE | W30: FALSE | X30: FALSE | Y30: FALSE | Z30: FALSE | AA30: FALSE | AB30: FALSE | AC30: FALSE | AD30: FALSE | AE30: FALSE | AF30: FALSE | AG30: FALSE | AH30: FALSE | AI30: FALSE | AJ30: FALSE | AK30: FALSE | AL30: FALSE | AO30: =COUNTIF(J30:AN30, "TRUE") -> 0 | AQ30: =IFERROR(__xludf.DUMMYFUNCTION("if(iserror(match(true,J30:AN30,0)),0,len(index(split(substitute(substitute(join("","",J30:AN30)&"","",""TRUE,"",""x""),""FALSE,"","",""),"",""),,counta(split(substitute(substitute(join("","",J30:AN30)&"","",""TRUE,"",""x""),""FALSE,"","",""),"","")))))"),0.0) -> 0 | AR30: =IFERROR(__xludf.DUMMYFUNCTION("arrayformula( if( sum(J30:AN30 + 0), max( len( split( concatenate( left(J30:AN30) ), ""F"" ) ) ), ""0"" ) )"),"0") -> 0 | AS30: 20 | AT30: =AO30/AS30 -> 0
A31: =A30+1 -> 9 | B31: =H30+1 -> 46076 | C31: =B31+1 -> 46077 | D31: =C31+1 -> 46078 | E31: =D31+1 -> 46079 | F31: =E31+1 -> 46080 | G31: =F31+1 -> 46081 | H31: =G31+1 -> 46082 | I31: 🏋🏾‍♂️Gym | J31: FALSE | K31: FALSE | L31: FALSE | M31: FALSE | N31: FALSE | O31: FALSE | P31: FALSE | Q31: FALSE | R31: FALSE | S31: FALSE | T31: FALSE | U31: FALSE | V31: FALSE | W31: FALSE | X31: FALSE | Y31: FALSE | Z31: FALSE | AA31: FALSE | AB31: FALSE | AC31: FALSE | AD31: FALSE | AE31: FALSE | AF31: FALSE | AG31: FALSE | AH31: FALSE | AI31: FALSE | AJ31: FALSE | AK31: FALSE | AL31: FALSE | AO31: =COUNTIF(J31:AN31, "TRUE") -> 0 | AQ31: =IFERROR(__xludf.DUMMYFUNCTION("if(iserror(match(true,J31:AN31,0)),0,len(index(split(substitute(substitute(join("","",J31:AN31)&"","",""TRUE,"",""x""),""FALSE,"","",""),"",""),,counta(split(substitute(substitute(join("","",J31:AN31)&"","",""TRUE,"",""x""),""FALSE,"","",""),"","")))))"),0.0) -> 0 | AR31: =IFERROR(__xludf.DUMMYFUNCTION("arrayformula( if( sum(J31:AN31 + 0), max( len( split( concatenate( left(J31:AN31) ), ""F"" ) ) ), ""0"" ) )"),"0") -> 0 | AS31: 15 | AT31: =AO31/AS31 -> 0
A32: =A31+1 -> 10 | B32: =H31+1 -> 46083 | C32: =B32+1 -> 46084 | D32: =C32+1 -> 46085 | E32: =D32+1 -> 46086 | F32: =E32+1 -> 46087 | G32: =F32+1 -> 46088 | H32: =G32+1 -> 46089 | J32: FALSE | K32: FALSE | L32: FALSE | M32: FALSE | N32: FALSE | O32: FALSE | P32: FALSE | Q32: FALSE | R32: FALSE | S32: FALSE | T32: FALSE | U32: FALSE | V32: FALSE | W32: FALSE | X32: FALSE | Y32: FALSE | Z32: FALSE | AA32: FALSE | AB32: FALSE | AC32: FALSE | AD32: FALSE | AE32: FALSE | AF32: FALSE | AG32: FALSE | AH32: FALSE | AI32: FALSE | AJ32: FALSE | AK32: FALSE | AL32: FALSE | AO32: =COUNTIF(J32:AN32, "TRUE") -> 0 | AQ32: =IFERROR(__xludf.DUMMYFUNCTION("if(iserror(match(true,J32:AN32,0)),0,len(index(split(substitute(substitute(join("","",J32:AN32)&"","",""TRUE,"",""x""),""FALSE,"","",""),"",""),,counta(split(substitute(substitute(join("","",J32:AN32)&"","",""TRUE,"",""x""),""FALSE,"","",""),"","")))))"),0.0) -> 0 | AR32: =IFERROR(__xludf.DUMMYFUNCTION("arrayformula( if( sum(J32:AN32 + 0), max( len( split( concatenate( left(J32:AN32) ), ""F"" ) ) ), ""0"" ) )"),"0") -> 0 | AS32: 15 | AT32: =AO32/AS32 -> 0
J33: FALSE | K33: FALSE | L33: FALSE | M33: FALSE | N33: FALSE | O33: FALSE | P33: FALSE | Q33: FALSE | R33: FALSE | S33: FALSE | T33: FALSE | U33: FALSE | V33: FALSE | W33: FALSE | X33: FALSE | Y33: FALSE | Z33: FALSE | AA33: FALSE | AB33: FALSE | AC33: FALSE | AD33: FALSE | AE33: FALSE | AF33: FALSE | AG33: FALSE | AH33: FALSE | AI33: FALSE | AJ33: FALSE | AK33: FALSE | AO33: =COUNTIF(J33:AN33, "TRUE") -> 0 | AQ33: =IFERROR(__xludf.DUMMYFUNCTION("if(iserror(match(true,J33:AN33,0)),0,len(index(split(substitute(substitute(join("","",J33:AN33)&"","",""TRUE,"",""x""),""FALSE,"","",""),"",""),,counta(split(substitute(substitute(join("","",J33:AN33)&"","",""TRUE,"",""x""),""FALSE,"","",""),"","")))))"),0.0) -> 0 | AR33: =IFERROR(__xludf.DUMMYFUNCTION("arrayformula( if( sum(J33:AN33 + 0), max( len( split( concatenate( left(J33:AN33) ), ""F"" ) ) ), ""0"" ) )"),"0") -> 0 | AS33: 15 | AT33: =AO33/AS33 -> 0
J34: FALSE | K34: FALSE | L34: FALSE | M34: FALSE | N34: FALSE | O34: FALSE | P34: FALSE | Q34: FALSE | R34: FALSE | S34: FALSE | T34: FALSE | U34: FALSE | V34: FALSE | W34: FALSE | X34: FALSE | Y34: FALSE | Z34: FALSE | AA34: FALSE | AB34: FALSE | AC34: FALSE | AD34: FALSE | AE34: FALSE | AF34: FALSE | AG34: FALSE | AH34: FALSE | AI34: FALSE | AJ34: FALSE | AK34: FALSE | AO34: =COUNTIF(J34:AN34, "TRUE") -> 0 | AQ34: =IFERROR(__xludf.DUMMYFUNCTION("if(iserror(match(true,J34:AN34,0)),0,len(index(split(substitute(substitute(join("","",J34:AN34)&"","",""TRUE,"",""x""),""FALSE,"","",""),"",""),,counta(split(substitute(substitute(join("","",J34:AN34)&"","",""TRUE,"",""x""),""FALSE,"","",""),"","")))))"),0.0) -> 0 | AR34: =IFERROR(__xludf.DUMMYFUNCTION("arrayformula( if( sum(J34:AN34 + 0), max( len( split( concatenate( left(J34:AN34) ), ""F"" ) ) ), ""0"" ) )"),"0") -> 0 | AS34: 15 | AT34: =AO34/AS34 -> 0
J35: FALSE | K35: FALSE | L35: FALSE | M35: FALSE | N35: FALSE | O35: FALSE | P35: FALSE | Q35: FALSE | R35: FALSE | S35: FALSE | T35: FALSE | U35: FALSE | V35: FALSE | W35: FALSE | X35: FALSE | Y35: FALSE | Z35: FALSE | AA35: FALSE | AB35: FALSE | AC35: FALSE | AD35: FALSE | AE35: FALSE | AF35: FALSE | AG35: FALSE | AH35: FALSE | AI35: FALSE | AJ35: FALSE | AK35: FALSE | AO35: =COUNTIF(J35:AN35, "TRUE") -> 0 | AQ35: =IFERROR(__xludf.DUMMYFUNCTION("if(iserror(match(true,J35:AN35,0)),0,len(index(split(substitute(substitute(join("","",J35:AN35)&"","",""TRUE,"",""x""),""FALSE,"","",""),"",""),,counta(split(substitute(substitute(join("","",J35:AN35)&"","",""TRUE,"",""x""),""FALSE,"","",""),"","")))))"),0.0) -> 0 | AR35: =IFERROR(__xludf.DUMMYFUNCTION("arrayformula( if( sum(J35:AN35 + 0), max( len( split( concatenate( left(J35:AN35) ), ""F"" ) ) ), ""0"" ) )"),"0") -> 0 | AS35: 15 | AT35: =AO35/AS35 -> 0
J36: FALSE | K36: FALSE | L36: FALSE | M36: FALSE | N36: FALSE | O36: FALSE | P36: FALSE | Q36: FALSE | R36: FALSE | S36: FALSE | T36: FALSE | U36: FALSE | V36: FALSE | W36: FALSE | X36: FALSE | Y36: FALSE | Z36: FALSE | AA36: FALSE | AB36: FALSE | AC36: FALSE | AD36: FALSE | AE36: FALSE | AF36: FALSE | AG36: FALSE | AH36: FALSE | AI36: FALSE | AJ36: FALSE | AK36: FALSE | AO36: =COUNTIF(J36:AN36, "TRUE") -> 0 | AQ36: =IFERROR(__xludf.DUMMYFUNCTION("if(iserror(match(true,J36:AN36,0)),0,len(index(split(substitute(substitute(join("","",J36:AN36)&"","",""TRUE,"",""x""),""FALSE,"","",""),"",""),,counta(split(substitute(substitute(join("","",J36:AN36)&"","",""TRUE,"",""x""),""FALSE,"","",""),"","")))))"),0.0) -> 0 | AR36: =IFERROR(__xludf.DUMMYFUNCTION("arrayformula( if( sum(J36:AN36 + 0), max( len( split( concatenate( left(J36:AN36) ), ""F"" ) ) ), ""0"" ) )"),"0") -> 0 | AS36: 15 | AT36: =AO36/AS36 -> 0
J37: FALSE | K37: FALSE | L37: FALSE | M37: FALSE | N37: FALSE | O37: FALSE | P37: FALSE | Q37: FALSE | R37: FALSE | S37: FALSE | T37: FALSE | U37: FALSE | V37: FALSE | W37: FALSE | X37: FALSE | Y37: FALSE | Z37: FALSE | AA37: FALSE | AB37: FALSE | AC37: FALSE | AD37: FALSE | AE37: FALSE | AF37: FALSE | AG37: FALSE | AH37: FALSE | AI37: FALSE | AJ37: FALSE | AK37: FALSE | AO37: =COUNTIF(J37:AN37, "TRUE") -> 0 | AQ37: =IFERROR(__xludf.DUMMYFUNCTION("if(iserror(match(true,J37:AN37,0)),0,len(index(split(substitute(substitute(join("","",J37:AN37)&"","",""TRUE,"",""x""),""FALSE,"","",""),"",""),,counta(split(substitute(substitute(join("","",J37:AN37)&"","",""TRUE,"",""x""),""FALSE,"","",""),"","")))))"),0.0) -> 0 | AR37: =IFERROR(__xludf.DUMMYFUNCTION("arrayformula( if( sum(J37:AN37 + 0), max( len( split( concatenate( left(J37:AN37) ), ""F"" ) ) ), ""0"" ) )"),"0") -> 0 | AS37: 15 | AT37: =AO37/AS37 -> 0
J38: FALSE | K38: FALSE | L38: FALSE | M38: FALSE | N38: FALSE | O38: FALSE | P38: FALSE | Q38: FALSE | R38: FALSE | S38: FALSE | T38: FALSE | U38: FALSE | V38: FALSE | W38: FALSE | X38: FALSE | Y38: FALSE | Z38: FALSE | AA38: FALSE | AB38: FALSE | AC38: FALSE | AD38: FALSE | AE38: FALSE | AF38: FALSE | AG38: FALSE | AH38: FALSE | AI38: FALSE | AJ38: FALSE | AK38: FALSE | AO38: =COUNTIF(J38:AN38, "TRUE") -> 0 | AQ38: =IFERROR(__xludf.DUMMYFUNCTION("if(iserror(match(true,J38:AN38,0)),0,len(index(split(substitute(substitute(join("","",J38:AN38)&"","",""TRUE,"",""x""),""FALSE,"","",""),"",""),,counta(split(substitute(substitute(join("","",J38:AN38)&"","",""TRUE,"",""x""),""FALSE,"","",""),"","")))))"),0.0) -> 0 | AR38: =IFERROR(__xludf.DUMMYFUNCTION("arrayformula( if( sum(J38:AN38 + 0), max( len( split( concatenate( left(J38:AN38) ), ""F"" ) ) ), ""0"" ) )"),"0") -> 0 | AS38: 15 | AT38: =AO38/AS38 -> 0
J39: FALSE | K39: FALSE | L39: FALSE | M39: FALSE | N39: FALSE | O39: FALSE | P39: FALSE | Q39: FALSE | R39: FALSE | S39: FALSE | T39: FALSE | U39: FALSE | V39: FALSE | W39: FALSE | X39: FALSE | Y39: FALSE | Z39: FALSE | AA39: FALSE | AB39: FALSE | AC39: FALSE | AD39: FALSE | AE39: FALSE | AF39: FALSE | AG39: FALSE | AH39: FALSE | AI39: FALSE | AJ39: FALSE | AK39: FALSE | AO39: =COUNTIF(J39:AN39, "TRUE") -> 0 | AQ39: =IFERROR(__xludf.DUMMYFUNCTION("if(iserror(match(true,J39:AN39,0)),0,len(index(split(substitute(substitute(join("","",J39:AN39)&"","",""TRUE,"",""x""),""FALSE,"","",""),"",""),,counta(split(substitute(substitute(join("","",J39:AN39)&"","",""TRUE,"",""x""),""FALSE,"","",""),"","")))))"),0.0) -> 0 | AR39: =IFERROR(__xludf.DUMMYFUNCTION("arrayformula( if( sum(J39:AN39 + 0), max( len( split( concatenate( left(J39:AN39) ), ""F"" ) ) ), ""0"" ) )"),"0") -> 0 | AS39: 15 | AT39: =AO39/AS39 -> 0
J40: FALSE | K40: FALSE | L40: FALSE | M40: FALSE | N40: FALSE | O40: FALSE | P40: FALSE | Q40: FALSE | R40: FALSE | S40: FALSE | T40: FALSE | U40: FALSE | V40: FALSE | W40: FALSE | X40: FALSE | Y40: FALSE | Z40: FALSE | AA40: FALSE | AB40: FALSE | AC40: FALSE | AD40: FALSE | AE40: FALSE | AF40: FALSE | AG40: FALSE | AH40: FALSE | AI40: FALSE | AJ40: FALSE | AK40: FALSE | AO40: =COUNTIF(J40:AN40, "TRUE") -> 0 | AQ40: =IFERROR(__xludf.DUMMYFUNCTION("if(iserror(match(true,J40:AN40,0)),0,len(index(split(substitute(substitute(join("","",J40:AN40)&"","",""TRUE,"",""x""),""FALSE,"","",""),"",""),,counta(split(substitute(substitute(join("","",J40:AN40)&"","",""TRUE,"",""x""),""FALSE,"","",""),"","")))))"),0.0) -> 0 | AR40: =IFERROR(__xludf.DUMMYFUNCTION("arrayformula( if( sum(J40:AN40 + 0), max( len( split( concatenate( left(J40:AN40) ), ""F"" ) ) ), ""0"" ) )"),"0") -> 0 | AS40: 15 | AT40: =AO40/AS40 -> 0
...
